Workbook
Name Slicer_Gender_Value: #N/A
Name Slicer_Order_Mode: #N/A

Sheet Data
A1: TX ID | B1: Product | C1: Quantity | D1: Unit Price | E1: Amount | F1: Order Date | G1: Ship Date | H1: Customer Gender | I1: Order Mode | J1: Rating C | K1: State | L1: County | M1: Days to Deliver | N1: Weeknum | O1: Gender Value
A2: TX500001 | B2: Shorts | C2: 1 | D2: 10.9 | E2: 10.9 | F2: 45658 | G2: 45663 | I2: App | J2: 4 | K2: California | L2: Alpine County | M2: =orders[[#This Row],[Ship Date]]-orders[[#This Row],[Order Date]] -> 5 | N2: =WEEKNUM(orders[[#This Row],[Order Date]]) -> 1 | O2: =_xlfn.IFS(orders[[#This Row],[Customer Gender]]="M","Male", orders[[#This Row],[Customer Gender]]="F","Female", orders[[#This Row],[Customer Gender]]="O","Other", TRUE,"Unknown") -> Unknown
A3: TX500002 | B3: Tank Tops | C3: 2 | D3: 30.6 | E3: 61.2 | F3: 45658 | G3: 45660 | H3: M | I3: App | J3: 4 | K3: California | L3: Contra Costa County | M3: =orders[[#This Row],[Ship Date]]-orders[[#This Row],[Order Date]] -> 2 | N3: =WEEKNUM(orders[[#This Row],[Order Date]]) -> 1 | O3: =_xlfn.IFS(orders[[#This Row],[Customer Gender]]="M","Male", orders[[#This Row],[Customer Gender]]="F","Female", orders[[#This Row],[Customer Gender]]="O","Other", TRUE,"Unknown") -> Male | Q3: Null Values
A4: TX500003 | B4: Sneakers | C4: 3 | D4: 109.4 | E4: 328.2 | F4: 45658 | G4: 45661 | H4: F | I4: App | J4: 3 | K4: California | L4: Fresno County | M4: =orders[[#This Row],[Ship Date]]-orders[[#This Row],[Order Date]] -> 3 | N4: =WEEKNUM(orders[[#This Row],[Order Date]]) -> 1 | O4: =_xlfn.IFS(orders[[#This Row],[Customer Gender]]="M","Male", orders[[#This Row],[Customer Gender]]="F","Female", orders[[#This Row],[Customer Gender]]="O","Other", TRUE,"Unknown") -> Female | Q4: Txn ID | R4: Product | S4: Quantity | T4: Unit Price | U4: Amount | V4: Order Date | W4: Ship Date | X4: Customer Gender | Y4: Order Mode | Z4: Rating | AA4: State | AB4: Country
A5: TX500004 | B5: Workout Tops | C5: 7 | D5: 37.7 | E5: 263.9 | F5: 45658 | G5: 45659 | H5: F | I5: App | J5: 4 | K5: California | L5: Fresno County | M5: =orders[[#This Row],[Ship Date]]-orders[[#This Row],[Order Date]] -> 1 | N5: =WEEKNUM(orders[[#This Row],[Order Date]]) -> 1 | O5: =_xlfn.IFS(orders[[#This Row],[Customer Gender]]="M","Male", orders[[#This Row],[Customer Gender]]="F","Female", orders[[#This Row],[Customer Gender]]="O","Other", TRUE,"Unknown") -> Female | Q5: =COUNTBLANK(orders[TX ID]) -> 0 | R5: =COUNTBLANK(orders[Product]) -> 0 | S5: =COUNTBLANK(orders[Quantity]) -> 0 | T5: =COUNTBLANK(orders[Unit Price]) -> 0 | U5: =COUNTBLANK(orders[Amount]) -> 0 | V5: =COUNTBLANK(orders[Order Date]) -> 0 | W5: =COUNTBLANK(orders[Ship Date]) -> 0 | X5: =COUNTBLANK(orders[Customer Gender]) -> 135 | Y5: =COUNTBLANK(orders[Order Mode]) -> 0 | Z5: =COUNTBLANK(orders[Rating C]) -> 0 | AA5: =COUNTBLANK(orders[State]) -> 0 | AB5: =COUNTBLANK(orders[County]) -> 0
A6: TX500005 | B6: Graphic Tees | C6: 3 | D6: 56.7 | E6: 170.1 | F6: 45658 | G6: 45661 | H6: F | I6: App | J6: 5 | K6: California | L6: Los Angeles County | M6: =orders[[#This Row],[Ship Date]]-orders[[#This Row],[Order Date]] -> 3 | N6: =WEEKNUM(orders[[#This Row],[Order Date]]) -> 1 | O6: =_xlfn.IFS(orders[[#This Row],[Customer Gender]]="M","Male", orders[[#This Row],[Customer Gender]]="F","Female", orders[[#This Row],[Customer Gender]]="O","Other", TRUE,"Unknown") -> Female
A7: TX500006 | B7: Tank Tops | C7: 12 | D7: 83.5 | E7: 1002 | F7: 45658 | G7: 45661 | H7: M | I7: Website | J7: 4 | K7: California | L7: Los Angeles County | M7: =orders[[#This Row],[Ship Date]]-orders[[#This Row],[Order Date]] -> 3 | N7: =WEEKNUM(orders[[#This Row],[Order Date]]) -> 1 | O7: =_xlfn.IFS(orders[[#This Row],[Customer Gender]]="M","Male", orders[[#This Row],[Customer Gender]]="F","Female", orders[[#This Row],[Customer Gender]]="O","Other", TRUE,"Unknown") -> Male
A8: TX500007 | B8: Sandals | C8: 1 | D8: 55.3 | E8: 55.3 | F8: 45658 | G8: 45659 | H8: F | I8: App | J8: 4 | K8: California | L8: Los Angeles County | M8: =orders[[#This Row],[Ship Date]]-orders[[#This Row],[Order Date]] -> 1 | N8: =WEEKNUM(orders[[#This Row],[Order Date]]) -> 1 | O8: =_xlfn.IFS(orders[[#This Row],[Customer Gender]]="M","Male", orders[[#This Row],[Customer Gender]]="F","Female", orders[[#This Row],[Customer Gender]]="O","Other", TRUE,"Unknown") -> Female
A9: TX500008 | B9: Jeans | C9: 2 | D9: 40.3 | E9: 80.6 | F9: 45658 | G9: 45659 | H9: M | I9: Target.com | J9: 5 | K9: California | L9: Los Angeles County | M9: =orders[[#This Row],[Ship Date]]-orders[[#This Row],[Order Date]] -> 1 | N9: =WEEKNUM(orders[[#This Row],[Order Date]]) -> 1 | O9: =_xlfn.IFS(orders[[#This Row],[Customer Gender]]="M","Male", orders[[#This Row],[Customer Gender]]="F","Female", orders[[#This Row],[Customer Gender]]="O","Other", TRUE,"Unknown") -> Male
A10: TX500009 | B10: Hoodies & Sweatshirts | C10: 11 | D10: 35.7 | E10: 392.7 | F10: 45658 | G10: 45659 | H10: F | I10: App | J10: 4 | K10: California | L10: Los Angeles County | M10: =orders[[#This Row],[Ship Date]]-orders[[#This Row],[Order Date]] -> 1 | N10: =WEEKNUM(orders[[#This Row],[Order Date]]) -> 1 | O10: =_xlfn.IFS(orders[[#This Row],[Customer Gender]]="M","Male", orders[[#This Row],[Customer Gender]]="F","Female", orders[[#This Row],[Customer Gender]]="O","Other", TRUE,"Unknown") -> Female
A11: TX500010 | B11: T-Shirts | C11: 7 | D11: 22.4 | E11: 156.8 | F11: 45658 | G11: 45661 | H11: M | I11: App | J11: 3 | K11: California | L11: Los Angeles County | M11: =orders[[#This Row],[Ship Date]]-orders[[#This Row],[Order Date]] -> 3 | N11: =WEEKNUM(orders[[#This Row],[Order Date]]) -> 1 | O11: =_xlfn.IFS(orders[[#This Row],[Customer Gender]]="M","Male", orders[[#This Row],[Customer Gender]]="F","Female", orders[[#This Row],[Customer Gender]]="O","Other", TRUE,"Unknown") -> Male
A12: TX500011 | B12: Sundresses | C12: 2 | D12: 54.4 | E12: 108.8 | F12: 45658 | G12: 45664 | H12: F | I12: App | J12: 4 | K12: California | L12: Los Angeles County | M12: =orders[[#This Row],[Ship Date]]-orders[[#This Row],[Order Date]] -> 6 | N12: =WEEKNUM(orders[[#This Row],[Order Date]]) -> 1 | O12: =_xlfn.IFS(orders[[#This Row],[Customer Gender]]="M","Male", orders[[#This Row],[Customer Gender]]="F","Female", orders[[#This Row],[Customer Gender]]="O","Other", TRUE,"Unknown") -> Female
A13: TX500012 | B13: Sundresses | C13: 2 | D13: 49 | E13: 98 | F13: 45658 | G13: 45660 | H13: F | I13: Target.com | J13: 3 | K13: California | L13: Los Angeles County | M13: =orders[[#This Row],[Ship Date]]-orders[[#This Row],[Order Date]] -> 2 | N13: =WEEKNUM(orders[[#This Row],[Order Date]]) -> 1 | O13: =_xlfn.IFS(orders[[#This Row],[Customer Gender]]="M","Male", orders[[#This Row],[Customer Gender]]="F","Female", orders[[#This Row],[Customer Gender]]="O","Other", TRUE,"Unknown") -> Female
A14: TX500013 | B14: Sandals | C14: 7 | D14: 118.6 | E14: 830.2 | F14: 45658 | G14: 45662 | H14: F | I14: Website | J14: 4 | K14: California | L14: Nevada County | M14: =orders[[#This Row],[Ship Date]]-orders[[#This Row],[Order Date]] -> 4 | N14: =WEEKNUM(orders[[#This Row],[Order Date]]) -> 1 | O14: =_xlfn.IFS(orders[[#This Row],[Customer Gender]]="M","Male", orders[[#This Row],[Customer Gender]]="F","Female", orders[[#This Row],[Customer Gender]]="O","Other", TRUE,"Unknown") -> Female
A15: TX500014 | B15: Jeans | C15: 27 | D15: 88.4 | E15: 2386.8 | F15: 45658 | G15: 45665 | H15: M | I15: Instagram | J15: 4 | K15: California | L15: Placer County | M15: =orders[[#This Row],[Ship Date]]-orders[[#This Row],[Order Date]] -> 7 | N15: =WEEKNUM(orders[[#This Row],[Order Date]]) -> 1 | O15: =_xlfn.IFS(orders[[#This Row],[Customer Gender]]="M","Male", orders[[#This Row],[Customer Gender]]="F","Female", orders[[#This Row],[Customer Gender]]="O","Other", TRUE,"Unknown") -> Male
A16: TX500015 | B16: Bikinis | C16: 1 | D16: 66.7 | E16: 66.7 | F16: 45658 | G16: 45661 | H16: M | I16: App | J16: 4 | K16: California | L16: Sacramento County | M16: =orders[[#This Row],[Ship Date]]-orders[[#This Row],[Order Date]] -> 3 | N16: =WEEKNUM(orders[[#This Row],[Order Date]]) -> 1 | O16: =_xlfn.IFS(orders[[#This Row],[Customer Gender]]="M","Male", orders[[#This Row],[Customer Gender]]="F","Female", orders[[#This Row],[Customer Gender]]="O","Other", TRUE,"Unknown") -> Male
A17: TX500016 | B17: Sundresses | C17: 10 | D17: 30.9 | E17: 309 | F17: 45658 | G17: 45659 | H17: M | I17: Website | J17: 5 | K17: California | L17: Sacramento County | M17: =orders[[#This Row],[Ship Date]]-orders[[#This Row],[Order Date]] -> 1 | N17: =WEEKNUM(orders[[#This Row],[Order Date]]) -> 1 | O17: =_xlfn.IFS(orders[[#This Row],[Customer Gender]]="M","Male", orders[[#This Row],[Customer Gender]]="F","Female", orders[[#This Row],[Customer Gender]]="O","Other", TRUE,"Unknown") -> Male
... A28: TX500027 | B28: Tank Tops | C28: 9 | D28: 38.7 | E28: 348.3 | F28: 45658 | G28: 45661 | H28: M | I28: Website | J28: 4 | K28: California | L28: Santa Barbara County | M28: =orders[[#This Row],[Ship Date]]-orders[[#This Row],[Order Date]] -> 3 | N28: =WEEKNUM(orders[[#This Row],[Order Date]]) -> 1 | O28: =_xlfn.IFS(orders[[#This Row],[Customer Gender]]="M","Male", orders[[#This Row],[Customer Gender]]="F","Female", orders[[#This Row],[Customer Gender]]="O","Other", TRUE,"Unknown") -> Male
A29: TX500028 | B29: Tote Bags | C29: 4 | D29: 57.2 | E29: 228.8 | F29: 45658 | G29: 45660 | I29: Website | J29: 5 | K29: California | L29: Santa Clara County | M29: =orders[[#This Row],[Ship Date]]-orders[[#This Row],[Order Date]] -> 2 | N29: =WEEKNUM(orders[[#This Row],[Order Date]]) -> 1 | O29: =_xlfn.IFS(orders[[#This Row],[Customer Gender]]="M","Male", orders[[#This Row],[Customer Gender]]="F","Female", orders[[#This Row],[Customer Gender]]="O","Other", TRUE,"Unknown") -> Unknown
A30: TX500029 | B30: Jeans | C30: 5 | D30: 50.9 | E30: 254.5 | F30: 45658 | G30: 45664 | I30: Website | J30: 5 | K30: California | L30: Tehama County | M30: =orders[[#This Row],[Ship Date]]-orders[[#This Row],[Order Date]] -> 6 | N30: =WEEKNUM(orders[[#This Row],[Order Date]]) -> 1 | O30: =_xlfn.IFS(orders[[#This Row],[Customer Gender]]="M","Male", orders[[#This Row],[Customer Gender]]="F","Female", orders[[#This Row],[Customer Gender]]="O","Other", TRUE,"Unknown") -> Unknown
A31: TX500030 | B31: Baseball Caps | C31: 7 | D31: 41 | E31: 287 | F31: 45658 | G31: 45662 | H31: F | I31: Website | J31: 4 | K31: California | L31: Ventura County | M31: =orders[[#This Row],[Ship Date]]-orders[[#This Row],[Order Date]] -> 4 | N31: =WEEKNUM(orders[[#This Row],[Order Date]]) -> 1 | O31: =_xlfn.IFS(orders[[#This Row],[Customer Gender]]="M","Male", orders[[#This Row],[Customer Gender]]="F","Female", orders[[#This Row],[Customer Gender]]="O","Other", TRUE,"Unknown") -> Female
A32: TX500031 | B32: T-Shirts | C32: 7 | D32: 19.1 | E32: 133.7 | F32: 45658 | G32: 45662 | H32: M | I32: App | J32: 5 | K32: California | L32: Calaveras County | M32: =orders[[#This Row],[Ship Date]]-orders[[#This Row],[Order Date]] -> 4 | N32: =WEEKNUM(orders[[#This Row],[Order Date]]) -> 1 | O32: =_xlfn.IFS(orders[[#This Row],[Customer Gender]]="M","Male", orders[[#This Row],[Customer Gender]]="F","Female", orders[[#This Row],[Customer Gender]]="O","Other", TRUE,"Unknown") -> Male
A33: TX500032 | B33: Sneakers | C33: 5 | D33: 166.1 | E33: 830.5 | F33: 45658 | G33: 45661 | H33: M | I33: App | J33: 4 | K33: California | L33: Inyo County | M33: =orders[[#This Row],[Ship Date]]-orders[[#This Row],[Order Date]] -> 3 | N33: =WEEKNUM(orders[[#This Row],[Order Date]]) -> 1 | O33: =_xlfn.IFS(orders[[#This Row],[Customer Gender]]="M","Male", orders[[#This Row],[Customer Gender]]="F","Female", orders[[#This Row],[Customer Gender]]="O","Other", TRUE,"Unknown") -> Male
A34: TX500033 | B34: Graphic Tees | C34: 3 | D34: 29.9 | E34: 89.7 | F34: 45658 | G34: 45659 | H34: M | I34: Instagram | J34: 4 | K34: California | L34: Los Angeles County | M34: =orders[[#This Row],[Ship Date]]-orders[[#This Row],[Order Date]] -> 1 | N34: =WEEKNUM(orders[[#This Row],[Order Date]]) -> 1 | O34: =_xlfn.IFS(orders[[#This Row],[Customer Gender]]="M","Male", orders[[#This Row],[Customer Gender]]="F","Female", orders[[#This Row],[Customer Gender]]="O","Other", TRUE,"Unknown") -> Male
A35: TX500034 | B35: Bikinis | C35: 6 | D35: 21.7 | E35: 130.2 | F35: 45658 | G35: 45660 | H35: O | I35: Target.com | J35: 5 | K35: California | L35: Los Angeles County | M35: =orders[[#This Row],[Ship Date]]-orders[[#This Row],[Order Date]] -> 2 | N35: =WEEKNUM(orders[[#This Row],[Order Date]]) -> 1 | O35: =_xlfn.IFS(orders[[#This Row],[Customer Gender]]="M","Male", orders[[#This Row],[Customer Gender]]="F","Female", orders[[#This Row],[Customer Gender]]="O","Other", TRUE,"Unknown") -> Other
A36: TX500035 | B36: Maxi Dresses | C36: 2 | D36: 32 | E36: 64 | F36: 45658 | G36: 45661 | H36: M | I36: App | J36: 5 | K36: California | L36: Los Angeles County | M36: =orders[[#This Row],[Ship Date]]-orders[[#This Row],[Order Date]] -> 3 | N36: =WEEKNUM(orders[[#This Row],[Order Date]]) -> 1 | O36: =_xlfn.IFS(orders[[#This Row],[Customer Gender]]="M","Male", orders[[#This Row],[Customer Gender]]="F","Female", orders[[#This Row],[Customer Gender]]="O","Other", TRUE,"Unknown") -> Male
A37: TX500036 | B37: T-Shirts | C37: 2 | D37: 15.8 | E37: 31.6 | F37: 45658 | G37: 45659 | H37: M | I37: Partner App | J37: 5 | K37: California | L37: Los Angeles County | M37: =orders[[#This Row],[Ship Date]]-orders[[#This Row],[Order Date]] -> 1 | N37: =WEEKNUM(orders[[#This Row],[Order Date]]) -> 1 | O37: =_xlfn.IFS(orders[[#This Row],[Customer Gender]]="M","Male", orders[[#This Row],[Customer Gender]]="F","Female", orders[[#This Row],[Customer Gender]]="O","Other", TRUE,"Unknown") -> Male
A38: TX500037 | B38: Sneakers | C38: 17 | D38: 203.1 | E38: 3452.7 | F38: 45658 | G38: 45662 | H38: M | I38: Instagram | J38: 3 | K38: California | L38: Los Angeles County | M38: =orders[[#This Row],[Ship Date]]-orders[[#This Row],[Order Date]] -> 4 | N38: =WEEKNUM(orders[[#This Row],[Order Date]]) -> 1 | O38: =_xlfn.IFS(orders[[#This Row],[Customer Gender]]="M","Male", orders[[#This Row],[Customer Gender]]="F","Female", orders[[#This Row],[Customer Gender]]="O","Other", TRUE,"Unknown") -> Male
A39: TX500038 | B39: Hoodies & Sweatshirts | C39: 13 | D39: 39 | E39: 507 | F39: 45658 | G39: 45664 | H39: M | I39: App | J39: 5 | K39: California | L39: Los Angeles County | M39: =orders[[#This Row],[Ship Date]]-orders[[#This Row],[Order Date]] -> 6 | N39: =WEEKNUM(orders[[#This Row],[Order Date]]) -> 1 | O39: =_xlfn.IFS(orders[[#This Row],[Customer Gender]]="M","Male", orders[[#This Row],[Customer Gender]]="F","Female", orders[[#This Row],[Customer Gender]]="O","Other", TRUE,"Unknown") -> Male
A40: TX500039 | B40: Bikinis | C40: 1 | D40: 26.5 | E40: 26.5 | F40: 45659 | G40: 45660 | H40: M | I40: Target.com | J40: 4 | K40: California | L40: Los Angeles County | M40: =orders[[#This Row],[Ship Date]]-orders[[#This Row],[Order Date]] -> 1 | N40: =WEEKNUM(orders[[#This Row],[Order Date]]) -> 1 | O40: =_xlfn.IFS(orders[[#This Row],[Customer Gender]]="M","Male", orders[[#This Row],[Customer Gender]]="F","Female", orders[[#This Row],[Customer Gender]]="O","Other", TRUE,"Unknown") -> Male
A41: TX500040 | B41: Sandals | C41: 1 | D41: 43.1 | E41: 43.1 | F41: 45659 | G41: 45660 | H41: F | I41: Target.com | J41: 3 | K41: California | L41: Los Angeles County | M41: =orders[[#This Row],[Ship Date]]-orders[[#This Row],[Order Date]] -> 1 | N41: =WEEKNUM(orders[[#This Row],[Order Date]]) -> 1 | O41: =_xlfn.IFS(orders[[#This Row],[Customer Gender]]="M","Male", orders[[#This Row],[Customer Gender]]="F","Female", orders[[#This Row],[Customer Gender]]="O","Other", TRUE,"Unknown") -> Female
A42: TX500041 | B42: Tank Tops | C42: 3 | D42: 139 | E42: 417 | F42: 45659 | G42: 45660 | H42: F | I42: Partner App | J42: 5 | K42: California | L42: Los Angeles County | M42: =orders[[#This Row],[Ship Date]]-orders[[#This Row],[Order Date]] -> 1 | N42: =WEEKNUM(orders[[#This Row],[Order Date]]) -> 1 | O42: =_xlfn.IFS(orders[[#This Row],[Customer Gender]]="M","Male", orders[[#This Row],[Customer Gender]]="F","Female", orders[[#This Row],[Customer Gender]]="O","Other", TRUE,"Unknown") -> Female
... A91: TX500090 | B91: Sneakers | C91: 1 | D91: 97.7 | E91: 97.7 | F91: 45661 | G91: 45664 | H91: F | I91: Website | J91: 4 | K91: California | L91: Los Angeles County | M91: =orders[[#This Row],[Ship Date]]-orders[[#This Row],[Order Date]] -> 3 | N91: =WEEKNUM(orders[[#This Row],[Order Date]]) -> 1 | O91: =_xlfn.IFS(orders[[#This Row],[Customer Gender]]="M","Male", orders[[#This Row],[Customer Gender]]="F","Female", orders[[#This Row],[Customer Gender]]="O","Other", TRUE,"Unknown") -> Female
A92: TX500091 | B92: Sundresses | C92: 5 | D92: 54.7 | E92: 273.5 | F92: 45661 | G92: 45664 | I92: App | J92: 5 | K92: California | L92: Riverside County | M92: =orders[[#This Row],[Ship Date]]-orders[[#This Row],[Order Date]] -> 3 | N92: =WEEKNUM(orders[[#This Row],[Order Date]]) -> 1 | O92: =_xlfn.IFS(orders[[#This Row],[Customer Gender]]="M","Male", orders[[#This Row],[Customer Gender]]="F","Female", orders[[#This Row],[Customer Gender]]="O","Other", TRUE,"Unknown") -> Unknown
A93: TX500092 | B93: Sneakers | C93: 6 | D93: 130.5 | E93: 783 | F93: 45661 | G93: 45663 | H93: F | I93: App | J93: 3 | K93: California | L93: Riverside County | M93: =orders[[#This Row],[Ship Date]]-orders[[#This Row],[Order Date]] -> 2 | N93: =WEEKNUM(orders[[#This Row],[Order Date]]) -> 1 | O93: =_xlfn.IFS(orders[[#This Row],[Customer Gender]]="M","Male", orders[[#This Row],[Customer Gender]]="F","Female", orders[[#This Row],[Customer Gender]]="O","Other", TRUE,"Unknown") -> Female
A94: TX500093 | B94: Maxi Dresses | C94: 2 | D94: 50.4 | E94: 100.8 | F94: 45661 | G94: 45663 | H94: M | I94: Target.com | J94: 5 | K94: California | L94: Sacramento County | M94: =orders[[#This Row],[Ship Date]]-orders[[#This Row],[Order Date]] -> 2 | N94: =WEEKNUM(orders[[#This Row],[Order Date]]) -> 1 | O94: =_xlfn.IFS(orders[[#This Row],[Customer Gender]]="M","Male", orders[[#This Row],[Customer Gender]]="F","Female", orders[[#This Row],[Customer Gender]]="O","Other", TRUE,"Unknown") -> Male
A95: TX500094 | B95: Jeans | C95: 13 | D95: 61.5 | E95: 799.5 | F95: 45661 | G95: 45662 | I95: Instagram | J95: 3 | K95: California | L95: Santa Clara County | M95: =orders[[#This Row],[Ship Date]]-orders[[#This Row],[Order Date]] -> 1 | N95: =WEEKNUM(orders[[#This Row],[Order Date]]) -> 1 | O95: =_xlfn.IFS(orders[[#This Row],[Customer Gender]]="M","Male", orders[[#This Row],[Customer Gender]]="F","Female", orders[[#This Row],[Customer Gender]]="O","Other", TRUE,"Unknown") -> Unknown
A96: TX500095 | B96: Sundresses | C96: 4 | D96: 30.1 | E96: 120.4 | F96: 45661 | G96: 45662 | H96: F | I96: App | J96: 5 | K96: California | L96: Alameda County | M96: =orders[[#This Row],[Ship Date]]-orders[[#This Row],[Order Date]] -> 1 | N96: =WEEKNUM(orders[[#This Row],[Order Date]]) -> 1 | O96: =_xlfn.IFS(orders[[#This Row],[Customer Gender]]="M","Male", orders[[#This Row],[Customer Gender]]="F","Female", orders[[#This Row],[Customer Gender]]="O","Other", TRUE,"Unknown") -> Female
A97: TX500096 | B97: Sneakers | C97: 5 | D97: 74.8 | E97: 374 | F97: 45661 | G97: 45662 | H97: F | I97: Website | J97: 4 | K97: California | L97: Contra Costa County | M97: =orders[[#This Row],[Ship Date]]-orders[[#This Row],[Order Date]] -> 1 | N97: =WEEKNUM(orders[[#This Row],[Order Date]]) -> 1 | O97: =_xlfn.IFS(orders[[#This Row],[Customer Gender]]="M","Male", orders[[#This Row],[Customer Gender]]="F","Female", orders[[#This Row],[Customer Gender]]="O","Other", TRUE,"Unknown") -> Female
A98: TX500097 | B98: Sunglasses | C98: 3 | D98: 64.9 | E98: 194.7 | F98: 45661 | G98: 45668 | H98: M | I98: App | J98: 4 | K98: California | L98: Fresno County | M98: =orders[[#This Row],[Ship Date]]-orders[[#This Row],[Order Date]] -> 7 | N98: =WEEKNUM(orders[[#This Row],[Order Date]]) -> 1 | O98: =_xlfn.IFS(orders[[#This Row],[Customer Gender]]="M","Male", orders[[#This Row],[Customer Gender]]="F","Female", orders[[#This Row],[Customer Gender]]="O","Other", TRUE,"Unknown") -> Male
...

Sheet Questions & KPIs
B2: KPIs
B3: Total Orders
B4: Total Quantity
B5: Total Amount
B6: Avg. Rating
B7: Avg. Days to Deliver
B10: Questions
B11: Trend in the last 13 weeks
B12: How our customers like to buy
B13: How many they buy?
B14: Which products are popular?
B15: Overall gender split
... B18: How happy are our customers?

Sheet Dashboard

Sheet Pivot
A2: KPI
A3: Count of TX ID | B3: Sum of Quantity | C3: Sum of Amount | D3: Average of Rating C | E3: Average of Days to Deliver | G3: Orders | H3: Quantity | I3: Amount | J3: Avg Rating | K3: Avg Days to deliver
A4: 2400 | B4: 11997 | C4: 649019.8 | D4: 3.9620833 | E4: 2.3425 | G4: =TEXT(Pivot!A4,"#,##") -> 2,400 | H4: =TEXT(Pivot!B4,"#,##") -> 11,997 | I4: =TEXT(Pivot!C4,"$ #,##,.0 K") -> $ 649.0 K | J4: =TEXT(Pivot!D4,"0.0") -> 4.0 | K4: =TEXT(Pivot!E4,"0.0") -> 2.3
A6: Week Wise Trend | E6: Quantity Wise Distribution
A8: Week | B8: Total Orders | C8: Total Amount | E8: Quantity | F8: Count of TX ID
A9: 1 | B9: 101 | C9: 32413.3 | E9: 1 | F9: 397
A10: 2 | B10: 155 | C10: 49563 | E10: 2 | F10: 540
A11: 3 | B11: 151 | C11: 41700.4 | E11: 3 | F11: 375
A12: 4 | B12: 175 | C12: 46782.6 | E12: 4 | F12: 246
A13: 5 | B13: 162 | C13: 42676.1 | E13: 5 | F13: 195
A14: 6 | B14: 240 | C14: 62910.7 | E14: 6-10 | F14: 414
A15: 7 | B15: 191 | C15: 50332.2 | E15: Above 10 | F15: 233
A16: 8 | B16: 236 | C16: 58760.6 | E16: Grand Total | F16: 2400
A17: 9 | B17: 202 | C17: 52017.3
A18: 10 | B18: 214 | C18: 64915.7
A19: 11 | B19: 189 | C19: 45943.8
A20: 12 | B20: 200 | C20: 55077.9
A21: 13 | B21: 184 | C21: 45926.2
A22: Grand Total | B22: 2400 | C22: 649019.8
A25: Product Popularity in terms of Quantity Sold | H25: Gender Split Contribution
A27: Sum of Quantity | B27: Column Labels | H27: Quantity | I27: Sum of Quantity
A28: Quantity | B28: Female | C28: Male | D28: Other | E28: Unknown | F28: Grand Total | H28: Female | I28: 6272
A29: T-Shirts | B29: 744 | C29: 713 | D29: 90 | E29: 98 | F29: 1645 | H29: Male | I29: 4672
A30: Jeans | B30: 716 | C30: 598 | D30: 18 | E30: 214 | F30: 1546 | H30: Other | I30: 317
A31: Sneakers | B31: 627 | C31: 393 | D31: 29 | E31: 137 | F31: 1186 | H31: Unknown | I31: 736
A32: Tank Tops | B32: 568 | C32: 306 | D32: 22 | E32: 16 | F32: 912 | H32: Grand Total | I32: 11997
A33: Bikinis | B33: 482 | C33: 295 | D33: 8 | E33: 22 | F33: 807
A34: Shorts | B34: 428 | C34: 293 | E34: 24 | F34: 745
A35: Sundresses | B35: 445 | C35: 202 | D35: 14 | E35: 39 | F35: 700
A36: Graphic Tees | B36: 431 | C36: 187 | D36: 14 | E36: 15 | F36: 647
A37: Hoodies & Sweatshirts | B37: 264 | C37: 318 | D37: 15 | E37: 9 | F37: 606
A38: Sandals | B38: 296 | C38: 275 | D38: 9 | E38: 23 | F38: 603
A39: Crop Tops | B39: 153 | C39: 246 | D39: 30 | E39: 8 | F39: 437
A40: Leggings | B40: 189 | C40: 168 | D40: 10 | E40: 31 | F40: 398
A41: Casual Dresses | B41: 234 | C41: 93 | D41: 19 | E41: 24 | F41: 370
A42: Workout Tops | B42: 146 | C42: 94 | D42: 4 | E42: 28 | F42: 272
A43: Pajama Sets | B43: 127 | C43: 118 | D43: 13 | E43: 12 | F43: 270
A44: Maxi Dresses | B44: 179 | C44: 76 | D44: 3 | F44: 258
A45: Sunglasses | B45: 99 | C45: 69 | D45: 3 | E45: 24 | F45: 195
A46: Tote Bags | B46: 75 | C46: 103 | D46: 4 | E46: 6 | F46: 188
...

Sheet Pivot 2
A1: Channel Wise Analysis (Total Amount Generated) | H1: Matrix
A3: Sum of Amount | B3: Column Labels
A4: Row Labels | B4: Female | C4: Male | D4: Other | E4: Unknown | F4: Grand Total | I4: =B4 -> Female | J4: =C4 -> Male | K4: =D4 -> Other | L4: =E4 -> Unknown
A5: App | B5: 0.18961825 | C5: 0.12262322 | D5: 0.010605378 | E5: 0.030599221 | F5: 0.35344607 | H5: =A5 -> App | I5: =B5 -> 0.18961825 | J5: =C5 -> 0.12262322 | K5: =D5 -> 0.010605378 | L5: =E5 -> 0.030599221
A6: Instagram | B6: 0.050283982 | C6: 0.043060782 | D6: 0.0015320026 | E6: 0.017794989 | F6: 0.11267176 | H6: =A6 -> Instagram | I6: =B6 -> 0.050283982 | J6: =C6 -> 0.043060782 | K6: =D6 -> 0.0015320026 | L6: =E6 -> 0.017794989
A7: Partner App | B7: 0.06349606 | C7: 0.04607163 | D7: 0.0023062471 | E7: 0.0038927934 | F7: 0.11576673 | H7: =A7 -> Partner App | I7: =B7 -> 0.06349606 | J7: =C7 -> 0.04607163 | K7: =D7 -> 0.0023062471 | L7: =E7 -> 0.0038927934
A8: Target.com | B8: 0.096337893 | C8: 0.067920116 | D8: 0.0054979833 | E8: 0.012933041 | F8: 0.18268903 | H8: =A8 -> Target.com | I8: =B8 -> 0.096337893 | J8: =C8 -> 0.067920116 | K8: =D8 -> 0.0054979833 | L8: =E8 -> 0.012933041
A9: Website | B9: 0.12522099 | C9: 0.09149274 | D9: 0.0063042761 | E9: 0.012408404 | F9: 0.23542641 | H9: =A9 -> Website | I9: =B9 -> 0.12522099 | J9: =C9 -> 0.09149274 | K9: =D9 -> 0.0063042761 | L9: =E9 -> 0.012408404
A10: Grand Total | B10: 0.52495717 | C10: 0.37116849 | D10: 0.026245886 | E10: 0.077628448 | F10: 1
A12: Channel Wise Analysis ( Total Orders)
A13: Count of TX ID | B13: Column Labels
A14: Row Labels | B14: Female | C14: Male | D14: Other | E14: Unknown | F14: Grand Total | I14: =B14 -> Female | J14: =C14 -> Male | K14: =D14 -> Other | L14: =E14 -> Unknown
A15: App | B15: 0.19 | C15: 0.13958333 | D15: 0.011666667 | E15: 0.020416667 | F15: 0.36166667 | H15: =A15 -> App | I15: =B15 -> 0.19 | J15: =C15 -> 0.13958333 | K15: =D15 -> 0.011666667 | L15: =E15 -> 0.020416667
A16: Instagram | B16: 0.049583333 | C16: 0.045416667 | D16: 0.0016666667 | E16: 0.0066666667 | F16: 0.10333333 | H16: =A16 -> Instagram | I16: =B16 -> 0.049583333 | J16: =C16 -> 0.045416667 | K16: =D16 -> 0.0016666667 | L16: =E16 -> 0.0066666667
A17: Partner App | B17: 0.057916667 | C17: 0.042083333 | D17: 0.0045833333 | E17: 0.0045833333 | F17: 0.10916667 | H17: =A17 -> Partner App | I17: =B17 -> 0.057916667 | J17: =C17 -> 0.042083333 | K17: =D17 -> 0.0045833333 | L17: =E17 -> 0.0045833333
A18: Target.com | B18: 0.094166667 | C18: 0.07625 | D18: 0.0066666667 | E18: 0.011666667 | F18: 0.18875 | H18: =A18 -> Target.com | I18: =B18 -> 0.094166667 | J18: =C18 -> 0.07625 | K18: =D18 -> 0.0066666667 | L18: =E18 -> 0.011666667
A19: Website | B19: 0.12125 | C19: 0.09625 | D19: 0.0066666667 | E19: 0.012916667 | F19: 0.23708333 | H19: =A19 -> Website | I19: =B19 -> 0.12125 | J19: =C19 -> 0.09625 | K19: =D19 -> 0.0066666667 | L19: =E19 -> 0.012916667
A20: Grand Total | B20: 0.51291667 | C20: 0.39958333 | D20: 0.03125 | E20: 0.05625 | F20: 1

Sheet Rough_Analysis
A2: Product Popularity in terms of Amount | F2: Product Popularity Region Wise ( Total Amount generated as per county for each product )
A3: Row Labels | B3: Sum of Quantity | C3: Average of Unit Price | D3: Sum of Amount | F3: Sum of Amount | G3: Column Labels
A4: Sneakers | B4: 1186 | C4: 105.71579 | D4: 127637.5 | F4: Row Labels | G4: Los Angeles County | H4: San Diego County | I4: Sacramento County | J4: Santa Clara County | K4: Alameda County | L4: San Francisco | M4: San Bernardino County | N4: Sonoma County | O4: San Mateo County | P4: Contra Costa County | Q4: Fresno County | R4: Kern County | S4: Stanislaus County | T4: Ventura County | U4: Orange County | V4: Placer County | W4: Riverside County | X4: Napa County | Y4: San Joaquin County | Z4: Santa Barbara County | AA4: Tulare County | AB4: Shasta County | AC4: Solano County | AD4: Merced County | AE4: Madera County | AF4: Imperial County | AG4: Santa Cruz County | AH4: Lake County | AI4: Humboldt County | AJ4: El Dorado County | AK4: Nevada County | AL4: Monterey County | AM4: Kings County | AN4: Marin County | AO4: Tuolumne County | AP4: San Benito County | AQ4: Butte County | AR4: Sutter County | AS4: Inyo County | AT4: Amador County | AU4: Yolo County | AV4: Mariposa County | AW4: San Luis Obispo County | AX4: Glenn County | AY4: Siskiyou County | AZ4: Calaveras County | BA4: Tehama County | BB4: Del Norte County | BC4: Yuba County | BD4: Mendocino County | BE4: Plumas County | BF4: Mono County | BG4: Trinity County | BH4: Colusa County | BI4: Sierra County | BJ4: Modoc County | BK4: Lassen County | BL4: Alpine County | BM4: Grand Total
A5: Jeans | B5: 1546 | C5: 70.540909 | D5: 112893.2 | F5: Sneakers | G5: 35896.3 | H5: 16473.4 | I5: 6866.7 | J5: 8583.2 | K5: 4318.8 | L5: 11332.5 | M5: 6520.9 | N5: 5481 | O5: 1693.2 | P5: 3701.9 | Q5: 3157.5 | R5: 2448.2 | S5: 2978.1 | T5: 2758.1 | U5: 315.3 | V5: 1347.5 | W5: 1232.5 | X5: 3242.8 | Y5: 401.2 | Z5: 225.6 | AA5: 530.4 | AB5: 1208.6 | AD5: 399.5 | AE5: 317.7 | AG5: 1672 | AI5: 488.8 | AJ5: 1589.7 | AK5: 248.4 | AN5: 248.2 | AP5: 189.4 | AS5: 830.5 | AT5: 348.2 | AW5: 213.8 | BC5: 285 | BE5: 92.6 | BM5: 127637.5
A6: Casual Dresses | B6: 370 | C6: 65.886667 | D6: 24664.6 | F6: Tank Tops | G6: 16899.8 | H6: 10212 | I6: 3091.2 | J6: 5930.9 | K6: 1544.4 | L6: 300.4 | M6: 2058 | N6: 1816.9 | O6: 2543.6 | P6: 1551.7 | Q6: 539.9 | R6: 847.2 | S6: 1084.8 | T6: 588.2 | U6: 1740 | V6: 998 | W6: 308.6 | X6: 1457.5 | Y6: 213.4 | Z6: 706.8 | AA6: 1050 | AC6: 255.2 | AD6: 614.6 | AI6: 441.6 | AK6: 84.8 | AM6: 47.1 | AQ6: 253.5 | AT6: 48 | AV6: 165.9 | BM6: 57394
A7: Workout Tops | B7: 272 | C7: 63.582258 | D7: 16668.2 | F7: Jeans | G7: 35472.2 | H7: 22916.8 | I7: 9013.8 | J7: 3899.9 | K7: 6582.7 | L7: 1015.6 | M7: 3350.4 | N7: 2237.8 | O7: 2867 | P7: 2740.7 | Q7: 1279.5 | R7: 1624.2 | S7: 394.6 | T7: 1445.4 | U7: 928.2 | V7: 4119.6 | W7: 1700.2 | X7: 716.8 | Y7: 624 | Z7: 502.4 | AA7: 433.7 | AB7: 751.4 | AC7: 2235 | AD7: 190.2 | AE7: 422.6 | AH7: 1484.4 | AJ7: 322.2 | AK7: 513.4 | AL7: 1536.6 | AP7: 355.5 | AR7: 261.6 | AT7: 323.4 | AY7: 103.6 | BA7: 254.5 | BG7: 146.1 | BH7: 127.2 | BM7: 112893.2
A8: Tank Tops | B8: 912 | C8: 62.734225 | D8: 57394 | F8: Bikinis | G8: 11427.9 | H8: 4888 | I8: 1659.9 | J8: 2727.8 | K8: 1780.7 | L8: 903.2 | M8: 436 | N8: 807.6 | O8: 366 | P8: 1668.5 | Q8: 465 | R8: 265.4 | S8: 499.2 | T8: 613.7 | V8: 369.6 | W8: 621.6 | Z8: 243 | AA8: 22.3 | AC8: 272.2 | AD8: 204.1 | AI8: 78.2 | AM8: 93.4 | AO8: 132.5 | AR8: 126 | AX8: 165 | BM8: 30836.8
A9: Hoodies & Sweatshirts | B9: 606 | C9: 60.217797 | D9: 35240.5 | F9: Workout Tops | G9: 3486.7 | H9: 2760.1 | I9: 564 | J9: 2269.8 | K9: 2779.9 | L9: 563.8 | M9: 680.2 | N9: 622.7 | O9: 947 | P9: 168.8 | Q9: 263.9 | R9: 405.4 | S9: 241.8 | Z9: 61.4 | AA9: 101.4 | AD9: 277.5 | AG9: 153.6 | AV9: 279.9 | BH9: 40.3 | BM9: 16668.2
A10: Leggings | B10: 398 | C10: 56.942029 | D10: 25206.5 | F10: T-Shirts | G10: 17082.9 | H10: 9516.2 | I10: 3333.5 | J10: 2234 | K10: 1784 | L10: 215.2 | M10: 971.3 | N10: 601.6 | O10: 1122.7 | P10: 2100.9 | Q10: 796.1 | R10: 640.9 | S10: 2116.1 | T10: 224.2 | U10: 744.6 | V10: 22 | W10: 1082.7 | X10: 97.5 | Y10: 933.3 | Z10: 385.6 | AA10: 586.9 | AB10: 80 | AD10: 33.8 | AF10: 422.6 | AG10: 108 | AH10: 407.1 | AI10: 152.4 | AK10: 21.9 | AL10: 39.3 | AM10: 254.6 | AN10: 450.7 | AP10: 315.2 | AQ10: 73.8 | AR10: 32 | AS10: 57 | AW10: 76.8 | AX10: 80.6 | AY10: 169.9 | AZ10: 133.7 | BD10: 54.3 | BM10: 49555.9
A11: Sunglasses | B11: 195 | C11: 55.313333 | D11: 10705.5 | F11: Hoodies & Sweatshirts | G11: 12600.1 | H11: 7943.1 | I11: 2201.8 | J11: 1664.8 | K11: 1110.4 | L11: 1609.9 | M11: 109.8 | N11: 563.6 | O11: 877.5 | P11: 962.7 | Q11: 47.1 | R11: 58.4 | S11: 855.2 | T11: 363.2 | U11: 548.6 | V11: 1358 | AB11: 581 | AE11: 489.6 | AF11: 543.6 | AG11: 137.7 | AM11: 235.2 | AN11: 270.6 | AP11: 108.6 | BM11: 35240.5
A12: Sandals | B12: 603 | C12: 53.748649 | D12: 31608.1 | F12: Tote Bags | G12: 2499 | H12: 753.8 | I12: 575.5 | J12: 1632.4 | L12: 75 | N12: 154.2 | P12: 86.4 | T12: 297.5 | AA12: 40.2 | AF12: 117.6 | AK12: 57 | BM12: 6288.6
A13: Sundresses | B13: 700 | C13: 47.813158 | D13: 32052.8 | F13: Sunglasses | G13: 2533.7 | H13: 627.2 | I13: 705.5 | J13: 1532 | K13: 638.7 | L13: 462 | M13: 372.9 | N13: 433.5 | O13: 338 | P13: 195.3 | Q13: 556.7 | R13: 134.8 | S13: 300.3 | T13: 253.5 | U13: 129.2 | V13: 224 | Y13: 204.6 | AA13: 333 | AB13: 138.6 | AE13: 592 | BM13: 10705.5
A14: Maxi Dresses | B14: 258 | C14: 45.032 | D14: 11025.2 | F14: Graphic Tees | G14: 9527 | H14: 1117.3 | I14: 1359.9 | J14: 1101.6 | K14: 1379.5 | L14: 207.6 | M14: 1244 | N14: 471 | O14: 150.5 | P14: 142.3 | Q14: 495.4 | R14: 655.3 | S14: 375.1 | T14: 677.2 | U14: 1120.5 | V14: 76 | W14: 400.8 | X14: 302.4 | Y14: 240 | Z14: 363.6 | AA14: 519.3 | AD14: 545.8 | AJ14: 160.3 | AN14: 65 | AQ14: 192.6 | AU14: 39.8 | AY14: 58.8 | BM14: 22988.6
A15: Crop Tops | B15: 437 | C15: 44.669737 | D15: 20170.4 | F15: Sandals | G15: 11504.4 | H15: 2686.5 | I15: 2182.4 | J15: 1076.4 | K15: 3993.8 | L15: 1526.9 | M15: 563.9 | N15: 435.8 | O15: 579.4 | P15: 118.8 | Q15: 204.4 | R15: 245 | S15: 392.1 | T15: 511.8 | U15: 1229.4 | W15: 135.8 | X15: 344 | Y15: 432.9 | Z15: 161.7 | AC15: 413.6 | AE15: 267.5 | AF15: 832 | AH15: 332.4 | AI15: 146.5 | AK15: 830.2 | AO15: 259.2 | AR15: 41.8 | AU15: 159.5 | BM15: 31608.1
A16: Pajama Sets | B16: 270 | C16: 41.65 | D16: 11263.6 | F16: Pajama Sets | G16: 5193.1 | H16: 528.9 | I16: 170 | J16: 1018 | K16: 216.8 | L16: 548.7 | M16: 143.6 | O16: 306.8 | P16: 368.6 | Q16: 355.3 | R16: 226 | S16: 381.6 | U16: 343 | Z16: 240.2 | AD16: 147.3 | AG16: 344 | AI16: 378.9 | AQ16: 352.8 | BM16: 11263.6
A17: Bikinis | B17: 807 | C17: 39.046296 | D17: 30836.8 | F17: Sundresses | G17: 13042.2 | H17: 4801.4 | I17: 2358.5 | J17: 1012.4 | K17: 595.6 | L17: 556.5 | M17: 505.9 | O17: 1128.6 | P17: 703.8 | Q17: 3033.7 | R17: 187.8 | S17: 371.6 | T17: 402.2 | U17: 214.9 | W17: 335.7 | Y17: 133.8 | Z17: 237.1 | AA17: 221.8 | AF17: 237.3 | AI17: 297.7 | AM17: 86.3 | AN17: 296.5 | AO17: 630 | AQ17: 189.9 | AT17: 80.7 | BA17: 68.5 | BB17: 322.4 | BM17: 32052.8
A18: Tote Bags | B18: 188 | C18: 36.963636 | D18: 6288.6 | F18: Casual Dresses | G18: 6672.1 | H18: 3531.1 | I18: 462.6 | J18: 804.6 | K18: 1500.4 | L18: 1827.2 | M18: 318.3 | N18: 653 | O18: 326.1 | Q18: 341.8 | R18: 1028.2 | T18: 904.6 | U18: 176.4 | V18: 306.6 | W18: 828 | X18: 80.7 | Y18: 2258 | Z18: 888.4 | AB18: 631.5 | AE18: 60.6 | AF18: 131.6 | AM18: 84.2 | AN18: 132.3 | AO18: 111.3 | AR18: 86.4 | AU18: 141.6 | BD18: 172.2 | BF18: 204.8 | BM18: 24664.6
A19: Graphic Tees | B19: 647 | C19: 35.067969 | D19: 22988.6 | F19: Leggings | G19: 10494.5 | H19: 1831.6 | I19: 373.8 | J19: 665.9 | K19: 756.4 | L19: 64.9 | M19: 1110.6 | N19: 5829.4 | O19: 534.5 | P19: 635.2 | Q19: 396.9 | R19: 184 | S19: 148.4 | T19: 168.4 | U19: 77.8 | V19: 51.4 | W19: 476.8 | Z19: 207 | AD19: 158.4 | AE19: 275.8 | AF19: 195.9 | AR19: 410.9 | AU19: 158 | BM19: 25206.5
A20: T-Shirts | B20: 1645 | C20: 30.238154 | D20: 49555.9 | F20: Maxi Dresses | G20: 4017.2 | H20: 1665.5 | I20: 949.7 | J20: 500.3 | K20: 372 | L20: 108.4 | O20: 499.6 | P20: 319.6 | Q20: 339.5 | R20: 246.8 | T20: 210.2 | U20: 116.5 | V20: 479.5 | W20: 164 | AF20: 181 | AI20: 145.4 | AM20: 340.4 | AO20: 272 | AX20: 97.6 | BM20: 11025.2
A21: Baseball Caps | B21: 147 | C21: 28.725714 | D21: 4597 | F21: Crop Tops | G21: 7712 | H21: 2187.3 | I21: 1025.7 | J21: 473.6 | K21: 1072.3 | L21: 144.8 | M21: 2333.1 | O21: 346.3 | R21: 1464.4 | U21: 1833.7 | W21: 382 | X21: 166 | AE21: 206.4 | AI21: 58.8 | AJ21: 20.6 | AK21: 53.6 | AM21: 357.6 | AZ21: 192.5 | BE21: 113.5 | BK21: 26.2 | BM21: 20170.4
A22: Jewelry | B22: 65 | C22: 25.9 | D22: 1906.4 | F22: Baseball Caps | G22: 1409.2 | H22: 1484 | J22: 196.7 | K22: 79 | L22: 152.4 | M22: 92 | N22: 27 | O22: 396 | P22: 171.9 | T22: 287 | W22: 22.6 | Z22: 112.2 | AA22: 42.6 | AD22: 96 | BJ22: 28.4 | BM22: 4597
A23: Shorts | B23: 745 | C23: 22.06129 | D23: 16316.4 | F23: Shorts | G23: 7416.1 | H23: 2222.2 | I23: 776.4 | J23: 91.9 | K23: 1345.6 | L23: 296.9 | M23: 178 | N23: 425.6 | O23: 1055.8 | P23: 411.6 | Q23: 362.2 | R23: 638.2 | S23: 47 | T23: 108.5 | U23: 162.3 | V23: 11.4 | X23: 37.2 | AA23: 96.9 | AD23: 23.2 | AE23: 55.2 | AG23: 32.2 | AL23: 32 | AP23: 161 | AU23: 116.4 | AW23: 102.2 | BD23: 47.1 | BG23: 21.6 | BI23: 30.8 | BL23: 10.9 | BM23: 16316.4
A24: Grand Total | B24: 11997 | C24: 53.827542 | D24: 649019.8 | F24: Jewelry | G24: 664.8 | H24: 220.7 | I24: 114 | J24: 32.8 | K24: 34 | N24: 378.9 | O24: 93.4 | P24: 120 | Q24: 27.6 | R24: 54 | T24: 55.4 | V24: 51.2 | AM24: 59.6 | BM24: 1906.4
F25: Grand Total | G25: 215551.2 | H25: 98367.1 | I25: 37784.9 | J25: 37449 | K25: 31885 | L25: 21911.9 | M25: 20988.9 | N25: 20939.6 | O25: 16172 | P25: 16168.7 | Q25: 12662.5 | R25: 11354.2 | S25: 10185.9 | T25: 9869.1 | U25: 9680.4 | V25: 9414.8 | W25: 7691.3 | X25: 6444.9 | Y25: 5441.2 | Z25: 4335 | AA25: 3978.5 | AB25: 3391.1 | AC25: 3176 | AD25: 2690.4 | AE25: 2687.4 | AF25: 2661.6 | AG25: 2447.5 | AH25: 2223.9 | AI25: 2188.3 | AJ25: 2092.8 | AK25: 1809.3 | AL25: 1607.9 | AM25: 1558.4 | AN25: 1463.3 | AO25: 1405 | AP25: 1129.7 | AQ25: 1062.6 | AR25: 958.7 | AS25: 887.5 | AT25: 800.3 | AU25: 615.3 | AV25: 445.8 | AW25: 392.8 | AX25: 343.2 | AY25: 332.3 | AZ25: 326.2 | BA25: 323 | BB25: 322.4 | BC25: 285 | BD25: 273.6 | BE25: 206.1 | BF25: 204.8 | BG25: 167.7 | BH25: 167.5 | BI25: 30.8 | BJ25: 28.4 | BK25: 26.2 | BL25: 10.9 | BM25: 649019.8
A30: Gender Split Distribution ( Total Orders per Gender for each product) | H30: Maximum Order Count per week
A32: Count of TX ID | B32: Column Labels | H32: Week Number | I32: Maximum Order Count
A33: Row Labels | B33: Female | C33: Male | D33: Other | E33: Unknown | F33: Grand Total | H33: 1 | I33: 41
A34: T-Shirts | B34: 151 | C34: 141 | D34: 15 | E34: 18 | F34: 325 | H34: 2 | I34: 54
A35: Sneakers | B35: 139 | C35: 88 | D35: 6 | E35: 14 | F35: 247 | H35: 3 | I35: 55
A36: Jeans | B36: 138 | C36: 114 | D36: 8 | E36: 26 | F36: 286 | H36: 4 | I36: 63
A37: Tank Tops | B37: 104 | C37: 69 | D37: 8 | E37: 6 | F37: 187 | H37: 5 | I37: 51
A38: Shorts | B38: 90 | C38: 60 | E38: 5 | F38: 155 | H38: 6 | I38: 78
A39: Sundresses | B39: 87 | C39: 50 | D39: 5 | E39: 10 | F39: 152 | H39: 7 | I39: 56
A40: Bikinis | B40: 85 | C40: 67 | D40: 3 | E40: 7 | F40: 162 | H40: 8 | I40: 68
A41: Graphic Tees | B41: 68 | C41: 51 | D41: 4 | E41: 5 | F41: 128 | H41: 9 | I41: 59
A42: Hoodies & Sweatshirts | B42: 63 | C42: 50 | D42: 2 | E42: 3 | F42: 118 | H42: 10 | I42: 68
A43: Sandals | B43: 53 | C43: 48 | D43: 4 | E43: 6 | F43: 111 | H43: 11 | I43: 53
A44: Casual Dresses | B44: 52 | C44: 27 | D44: 5 | E44: 6 | F44: 90 | H44: 12 | I44: 70
A45: Maxi Dresses | B45: 32 | C45: 17 | D45: 1 | F45: 50 | H45: 13 | I45: 65
A46: Workout Tops | B46: 31 | C46: 24 | D46: 1 | E46: 6 | F46: 62 | H46: Grand Total | I46: 781
...
